Workbook

Sheet ⚔ Armes
A1: ⚔ FORGERON DE SOLITUDE — Catalogue des Armes
A2: Catégorie | B2: Arme | C2: M.O. | D2: Fer | E2: Acier | F2: Orichalque | G2: Vif-argent | H2: Métal dwemer | I2: Pierre de lune | J2: Corindon | K2: Petit bois | L2: Cuir | M2: Bande cuir | N2: Or | O2: Malachite | P2: Ébonite | Q2: Coût mat. | R2: ⚡ TOTAL
A3: FER
A4: Fer | B4: Arc | C4: 5 | K4: 8 | L4: 1 | M4: 2 | Q4: =IF(D4="",0,D4*'💰 Prix matériaux'!$B$3)+IF(E4="",0,E4*'💰 Prix matériaux'!$B$4)+IF(F4="",0,F4*'💰 Prix matériaux'!$B$5)+IF(G4="",0,G4*'💰 Prix matériaux'!$B$6)+IF(H4="",0,H4*'💰 Prix matériaux'!$B$7)+IF(I4="",0,I4*'💰 Prix matériaux'!$B$8)+IF(J4="",0,J4*'💰 Prix matériaux'!$B$9)+IF(K4="",0,K4*'💰 Prix matériaux'!$B$10)+IF(L4="",0,L4*'💰 Prix matériaux'!$B$11)+IF(M4="",0,M4*'💰 Prix matériaux'!$B$12)+IF(N4="",0,N4*'💰 Prix matériaux'!$B$13)+IF(O4="",0,O4*'💰 Prix matériaux'!$B$15)+IF(P4="",0,P4*'💰 Prix matériaux'!$B$16) -> 14 | R4: =C4+Q4 -> 19
A5: Fer | B5: Dague | C5: 5 | D5: 1 | M5: 1 | Q5: =IF(D5="",0,D5*'💰 Prix matériaux'!$B$3)+IF(E5="",0,E5*'💰 Prix matériaux'!$B$4)+IF(F5="",0,F5*'💰 Prix matériaux'!$B$5)+IF(G5="",0,G5*'💰 Prix matériaux'!$B$6)+IF(H5="",0,H5*'💰 Prix matériaux'!$B$7)+IF(I5="",0,I5*'💰 Prix matériaux'!$B$8)+IF(J5="",0,J5*'💰 Prix matériaux'!$B$9)+IF(K5="",0,K5*'💰 Prix matériaux'!$B$10)+IF(L5="",0,L5*'💰 Prix matériaux'!$B$11)+IF(M5="",0,M5*'💰 Prix matériaux'!$B$12)+IF(N5="",0,N5*'💰 Prix matériaux'!$B$13)+IF(O5="",0,O5*'💰 Prix matériaux'!$B$15)+IF(P5="",0,P5*'💰 Prix matériaux'!$B$16) -> 5 | R5: =C5+Q5 -> 10
A6: Fer | B6: Espadon | C6: 5 | D6: 4 | M6: 2 | Q6: =IF(D6="",0,D6*'💰 Prix matériaux'!$B$3)+IF(E6="",0,E6*'💰 Prix matériaux'!$B$4)+IF(F6="",0,F6*'💰 Prix matériaux'!$B$5)+IF(G6="",0,G6*'💰 Prix matériaux'!$B$6)+IF(H6="",0,H6*'💰 Prix matériaux'!$B$7)+IF(I6="",0,I6*'💰 Prix matériaux'!$B$8)+IF(J6="",0,J6*'💰 Prix matériaux'!$B$9)+IF(K6="",0,K6*'💰 Prix matériaux'!$B$10)+IF(L6="",0,L6*'💰 Prix matériaux'!$B$11)+IF(M6="",0,M6*'💰 Prix matériaux'!$B$12)+IF(N6="",0,N6*'💰 Prix matériaux'!$B$13)+IF(O6="",0,O6*'💰 Prix matériaux'!$B$15)+IF(P6="",0,P6*'💰 Prix matériaux'!$B$16) -> 18 | R6: =C6+Q6 -> 23
A7: Fer | B7: Flèche | C7: 5 | D7: 1 | K7: 1 | Q7: =IF(D7="",0,D7*'💰 Prix matériaux'!$B$3)+IF(E7="",0,E7*'💰 Prix matériaux'!$B$4)+IF(F7="",0,F7*'💰 Prix matériaux'!$B$5)+IF(G7="",0,G7*'💰 Prix matériaux'!$B$6)+IF(H7="",0,H7*'💰 Prix matériaux'!$B$7)+IF(I7="",0,I7*'💰 Prix matériaux'!$B$8)+IF(J7="",0,J7*'💰 Prix matériaux'!$B$9)+IF(K7="",0,K7*'💰 Prix matériaux'!$B$10)+IF(L7="",0,L7*'💰 Prix matériaux'!$B$11)+IF(M7="",0,M7*'💰 Prix matériaux'!$B$12)+IF(N7="",0,N7*'💰 Prix matériaux'!$B$13)+IF(O7="",0,O7*'💰 Prix matériaux'!$B$15)+IF(P7="",0,P7*'💰 Prix matériaux'!$B$16) -> 5 | R7: =C7+Q7 -> 10
A8: Fer | B8: Hache d'arme | C8: 5 | D8: 4 | M8: 2 | Q8: =IF(D8="",0,D8*'💰 Prix matériaux'!$B$3)+IF(E8="",0,E8*'💰 Prix matériaux'!$B$4)+IF(F8="",0,F8*'💰 Prix matériaux'!$B$5)+IF(G8="",0,G8*'💰 Prix matériaux'!$B$6)+IF(H8="",0,H8*'💰 Prix matériaux'!$B$7)+IF(I8="",0,I8*'💰 Prix matériaux'!$B$8)+IF(J8="",0,J8*'💰 Prix matériaux'!$B$9)+IF(K8="",0,K8*'💰 Prix matériaux'!$B$10)+IF(L8="",0,L8*'💰 Prix matériaux'!$B$11)+IF(M8="",0,M8*'💰 Prix matériaux'!$B$12)+IF(N8="",0,N8*'💰 Prix matériaux'!$B$13)+IF(O8="",0,O8*'💰 Prix matériaux'!$B$15)+IF(P8="",0,P8*'💰 Prix matériaux'!$B$16) -> 18 | R8: =C8+Q8 -> 23
A9: Fer | B9: Hache | C9: 5 | D9: 2 | M9: 2 | Q9: =IF(D9="",0,D9*'💰 Prix matériaux'!$B$3)+IF(E9="",0,E9*'💰 Prix matériaux'!$B$4)+IF(F9="",0,F9*'💰 Prix matériaux'!$B$5)+IF(G9="",0,G9*'💰 Prix matériaux'!$B$6)+IF(H9="",0,H9*'💰 Prix matériaux'!$B$7)+IF(I9="",0,I9*'💰 Prix matériaux'!$B$8)+IF(J9="",0,J9*'💰 Prix matériaux'!$B$9)+IF(K9="",0,K9*'💰 Prix matériaux'!$B$10)+IF(L9="",0,L9*'💰 Prix matériaux'!$B$11)+IF(M9="",0,M9*'💰 Prix matériaux'!$B$12)+IF(N9="",0,N9*'💰 Prix matériaux'!$B$13)+IF(O9="",0,O9*'💰 Prix matériaux'!$B$15)+IF(P9="",0,P9*'💰 Prix matériaux'!$B$16) -> 10 | R9: =C9+Q9 -> 15
A10: Fer | B10: Marteau de guerre | C10: 5 | D10: 4 | M10: 3 | Q10: =IF(D10="",0,D10*'💰 Prix matériaux'!$B$3)+IF(E10="",0,E10*'💰 Prix matériaux'!$B$4)+IF(F10="",0,F10*'💰 Prix matériaux'!$B$5)+IF(G10="",0,G10*'💰 Prix matériaux'!$B$6)+IF(H10="",0,H10*'💰 Prix matériaux'!$B$7)+IF(I10="",0,I10*'💰 Prix matériaux'!$B$8)+IF(J10="",0,J10*'💰 Prix matériaux'!$B$9)+IF(K10="",0,K10*'💰 Prix matériaux'!$B$10)+IF(L10="",0,L10*'💰 Prix matériaux'!$B$11)+IF(M10="",0,M10*'💰 Prix matériaux'!$B$12)+IF(N10="",0,N10*'💰 Prix matériaux'!$B$13)+IF(O10="",0,O10*'💰 Prix matériaux'!$B$15)+IF(P10="",0,P10*'💰 Prix matériaux'!$B$16) -> 19 | R10: =C10+Q10 -> 24
A11: Fer | B11: Masse | C11: 5 | D11: 3 | M11: 2 | Q11: =IF(D11="",0,D11*'💰 Prix matériaux'!$B$3)+IF(E11="",0,E11*'💰 Prix matériaux'!$B$4)+IF(F11="",0,F11*'💰 Prix matériaux'!$B$5)+IF(G11="",0,G11*'💰 Prix matériaux'!$B$6)+IF(H11="",0,H11*'💰 Prix matériaux'!$B$7)+IF(I11="",0,I11*'💰 Prix matériaux'!$B$8)+IF(J11="",0,J11*'💰 Prix matériaux'!$B$9)+IF(K11="",0,K11*'💰 Prix matériaux'!$B$10)+IF(L11="",0,L11*'💰 Prix matériaux'!$B$11)+IF(M11="",0,M11*'💰 Prix matériaux'!$B$12)+IF(N11="",0,N11*'💰 Prix matériaux'!$B$13)+IF(O11="",0,O11*'💰 Prix matériaux'!$B$15)+IF(P11="",0,P11*'💰 Prix matériaux'!$B$16) -> 14 | R11: =C11+Q11 -> 19
A12: Fer | B12: Épée | C12: 5 | D12: 2 | M12: 1 | Q12: =IF(D12="",0,D12*'💰 Prix matériaux'!$B$3)+IF(E12="",0,E12*'💰 Prix matériaux'!$B$4)+IF(F12="",0,F12*'💰 Prix matériaux'!$B$5)+IF(G12="",0,G12*'💰 Prix matériaux'!$B$6)+IF(H12="",0,H12*'💰 Prix matériaux'!$B$7)+IF(I12="",0,I12*'💰 Prix matériaux'!$B$8)+IF(J12="",0,J12*'💰 Prix matériaux'!$B$9)+IF(K12="",0,K12*'💰 Prix matériaux'!$B$10)+IF(L12="",0,L12*'💰 Prix matériaux'!$B$11)+IF(M12="",0,M12*'💰 Prix matériaux'!$B$12)+IF(N12="",0,N12*'💰 Prix matériaux'!$B$13)+IF(O12="",0,O12*'💰 Prix matériaux'!$B$15)+IF(P12="",0,P12*'💰 Prix matériaux'!$B$16) -> 9 | R12: =C12+Q12 -> 14
A13: ACIER
A14: Acier | B14: Arc | C14: 10 | E14: 2 | K14: 8 | L14: 1 | M14: 2 | Q14: =IF(D14="",0,D14*'💰 Prix matériaux'!$B$3)+IF(E14="",0,E14*'💰 Prix matériaux'!$B$4)+IF(F14="",0,F14*'💰 Prix matériaux'!$B$5)+IF(G14="",0,G14*'💰 Prix matériaux'!$B$6)+IF(H14="",0,H14*'💰 Prix matériaux'!$B$7)+IF(I14="",0,I14*'💰 Prix matériaux'!$B$8)+IF(J14="",0,J14*'💰 Prix matériaux'!$B$9)+IF(K14="",0,K14*'💰 Prix matériaux'!$B$10)+IF(L14="",0,L14*'💰 Prix matériaux'!$B$11)+IF(M14="",0,M14*'💰 Prix matériaux'!$B$12)+IF(N14="",0,N14*'💰 Prix matériaux'!$B$13)+IF(O14="",0,O14*'💰 Prix matériaux'!$B$15)+IF(P14="",0,P14*'💰 Prix matériaux'!$B$16) -> 28 | R14: =C14+Q14 -> 38
A15: Acier | B15: Dague | C15: 10 | D15: 1 | E15: 1 | M15: 1 | Q15: =IF(D15="",0,D15*'💰 Prix matériaux'!$B$3)+IF(E15="",0,E15*'💰 Prix matériaux'!$B$4)+IF(F15="",0,F15*'💰 Prix matériaux'!$B$5)+IF(G15="",0,G15*'💰 Prix matériaux'!$B$6)+IF(H15="",0,H15*'💰 Prix matériaux'!$B$7)+IF(I15="",0,I15*'💰 Prix matériaux'!$B$8)+IF(J15="",0,J15*'💰 Prix matériaux'!$B$9)+IF(K15="",0,K15*'💰 Prix matériaux'!$B$10)+IF(L15="",0,L15*'💰 Prix matériaux'!$B$11)+IF(M15="",0,M15*'💰 Prix matériaux'!$B$12)+IF(N15="",0,N15*'💰 Prix matériaux'!$B$13)+IF(O15="",0,O15*'💰 Prix matériaux'!$B$15)+IF(P15="",0,P15*'💰 Prix matériaux'!$B$16) -> 12 | R15: =C15+Q15 -> 22
A16: Acier | B16: Espadon | C16: 10 | D16: 2 | E16: 4 | M16: 3 | Q16: =IF(D16="",0,D16*'💰 Prix matériaux'!$B$3)+IF(E16="",0,E16*'💰 Prix matériaux'!$B$4)+IF(F16="",0,F16*'💰 Prix matériaux'!$B$5)+IF(G16="",0,G16*'💰 Prix matériaux'!$B$6)+IF(H16="",0,H16*'💰 Prix matériaux'!$B$7)+IF(I16="",0,I16*'💰 Prix matériaux'!$B$8)+IF(J16="",0,J16*'💰 Prix matériaux'!$B$9)+IF(K16="",0,K16*'💰 Prix matériaux'!$B$10)+IF(L16="",0,L16*'💰 Prix matériaux'!$B$11)+IF(M16="",0,M16*'💰 Prix matériaux'!$B$12)+IF(N16="",0,N16*'💰 Prix matériaux'!$B$13)+IF(O16="",0,O16*'💰 Prix matériaux'!$B$15)+IF(P16="",0,P16*'💰 Prix matériaux'!$B$16) -> 39 | R16: =C16+Q16 -> 49
A17: Acier | B17: Flèche | C17: 10 | E17: 1 | K17: 1 | Q17: =IF(D17="",0,D17*'💰 Prix matériaux'!$B$3)+IF(E17="",0,E17*'💰 Prix matériaux'!$B$4)+IF(F17="",0,F17*'💰 Prix matériaux'!$B$5)+IF(G17="",0,G17*'💰 Prix matériaux'!$B$6)+IF(H17="",0,H17*'💰 Prix matériaux'!$B$7)+IF(I17="",0,I17*'💰 Prix matériaux'!$B$8)+IF(J17="",0,J17*'💰 Prix matériaux'!$B$9)+IF(K17="",0,K17*'💰 Prix matériaux'!$B$10)+IF(L17="",0,L17*'💰 Prix matériaux'!$B$11)+IF(M17="",0,M17*'💰 Prix matériaux'!$B$12)+IF(N17="",0,N17*'💰 Prix matériaux'!$B$13)+IF(O17="",0,O17*'💰 Prix matériaux'!$B$15)+IF(P17="",0,P17*'💰 Prix matériaux'!$B$16) -> 8 | R17: =C17+Q17 -> 18
A18: Acier | B18: Hache | C18: 10 | D18: 1 | E18: 2 | M18: 2 | Q18: =IF(D18="",0,D18*'💰 Prix matériaux'!$B$3)+IF(E18="",0,E18*'💰 Prix matériaux'!$B$4)+IF(F18="",0,F18*'💰 Prix matériaux'!$B$5)+IF(G18="",0,G18*'💰 Prix matériaux'!$B$6)+IF(H18="",0,H18*'💰 Prix matériaux'!$B$7)+IF(I18="",0,I18*'💰 Prix matériaux'!$B$8)+IF(J18="",0,J18*'💰 Prix matériaux'!$B$9)+IF(K18="",0,K18*'💰 Prix matériaux'!$B$10)+IF(L18="",0,L18*'💰 Prix matériaux'!$B$11)+IF(M18="",0,M18*'💰 Prix matériaux'!$B$12)+IF(N18="",0,N18*'💰 Prix matériaux'!$B$13)+IF(O18="",0,O18*'💰 Prix matériaux'!$B$15)+IF(P18="",0,P18*'💰 Prix matériaux'!$B$16) -> 20 | R18: =C18+Q18 -> 30
A19: Acier | B19: Hache d'arme | C19: 15 | D19: 1 | E19: 4 | M19: 2 | Q19: =IF(D19="",0,D19*'💰 Prix matériaux'!$B$3)+IF(E19="",0,E19*'💰 Prix matériaux'!$B$4)+IF(F19="",0,F19*'💰 Prix matériaux'!$B$5)+IF(G19="",0,G19*'💰 Prix matériaux'!$B$6)+IF(H19="",0,H19*'💰 Prix matériaux'!$B$7)+IF(I19="",0,I19*'💰 Prix matériaux'!$B$8)+IF(J19="",0,J19*'💰 Prix matériaux'!$B$9)+IF(K19="",0,K19*'💰 Prix matériaux'!$B$10)+IF(L19="",0,L19*'💰 Prix matériaux'!$B$11)+IF(M19="",0,M19*'💰 Prix matériaux'!$B$12)+IF(N19="",0,N19*'💰 Prix matériaux'!$B$13)+IF(O19="",0,O19*'💰 Prix matériaux'!$B$15)+IF(P19="",0,P19*'💰 Prix matériaux'!$B$16) -> 34 | R19: =C19+Q19 -> 49
A20: Acier | B20: Marteau de guerre | C20: 10 | D20: 1 | E20: 4 | M20: 3 | Q20: =IF(D20="",0,D20*'💰 Prix matériaux'!$B$3)+IF(E20="",0,E20*'💰 Prix matériaux'!$B$4)+IF(F20="",0,F20*'💰 Prix matériaux'!$B$5)+IF(G20="",0,G20*'💰 Prix matériaux'!$B$6)+IF(H20="",0,H20*'💰 Prix matériaux'!$B$7)+IF(I20="",0,I20*'💰 Prix matériaux'!$B$8)+IF(J20="",0,J20*'💰 Prix matériaux'!$B$9)+IF(K20="",0,K20*'💰 Prix matériaux'!$B$10)+IF(L20="",0,L20*'💰 Prix matériaux'!$B$11)+IF(M20="",0,M20*'💰 Prix matériaux'!$B$12)+IF(N20="",0,N20*'💰 Prix matériaux'!$B$13)+IF(O20="",0,O20*'💰 Prix matériaux'!$B$15)+IF(P20="",0,P20*'💰 Prix matériaux'!$B$16) -> 35 | R20: =C20+Q20 -> 45
A21: Acier | B21: Masse | C21: 10 | D21: 1 | E21: 3 | M21: 1 | Q21: =IF(D21="",0,D21*'💰 Prix matériaux'!$B$3)+IF(E21="",0,E21*'💰 Prix matériaux'!$B$4)+IF(F21="",0,F21*'💰 Prix matériaux'!$B$5)+IF(G21="",0,G21*'💰 Prix matériaux'!$B$6)+IF(H21="",0,H21*'💰 Prix matériaux'!$B$7)+IF(I21="",0,I21*'💰 Prix matériaux'!$B$8)+IF(J21="",0,J21*'💰 Prix matériaux'!$B$9)+IF(K21="",0,K21*'💰 Prix matériaux'!$B$10)+IF(L21="",0,L21*'💰 Prix matériaux'!$B$11)+IF(M21="",0,M21*'💰 Prix matériaux'!$B$12)+IF(N21="",0,N21*'💰 Prix matériaux'!$B$13)+IF(O21="",0,O21*'💰 Prix matériaux'!$B$15)+IF(P21="",0,P21*'💰 Prix matériaux'!$B$16) -> 26 | R21: =C21+Q21 -> 36
A22: Acier | B22: Épée | C22: 10 | D22: 1 | E22: 2 | M22: 1 | Q22: =IF(D22="",0,D22*'💰 Prix matériaux'!$B$3)+IF(E22="",0,E22*'💰 Prix matériaux'!$B$4)+IF(F22="",0,F22*'💰 Prix matériaux'!$B$5)+IF(G22="",0,G22*'💰 Prix matériaux'!$B$6)+IF(H22="",0,H22*'💰 Prix matériaux'!$B$7)+IF(I22="",0,I22*'💰 Prix matériaux'!$B$8)+IF(J22="",0,J22*'💰 Prix matériaux'!$B$9)+IF(K22="",0,K22*'💰 Prix matériaux'!$B$10)+IF(L22="",0,L22*'💰 Prix matériaux'!$B$11)+IF(M22="",0,M22*'💰 Prix matériaux'!$B$12)+IF(N22="",0,N22*'💰 Prix matériaux'!$B$13)+IF(O22="",0,O22*'💰 Prix matériaux'!$B$15)+IF(P22="",0,P22*'💰 Prix matériaux'!$B$16) -> 19 | R22: =C22+Q22 -> 29
A23: ALTMER
A24: Altmer | B24: Arc | C24: 30 | G24: 1 | I24: 2 | Q24: =IF(D24="",0,D24*'💰 Prix matériaux'!$B$3)+IF(E24="",0,E24*'💰 Prix matériaux'!$B$4)+IF(F24="",0,F24*'💰 Prix matériaux'!$B$5)+IF(G24="",0,G24*'💰 Prix matériaux'!$B$6)+IF(H24="",0,H24*'💰 Prix matériaux'!$B$7)+IF(I24="",0,I24*'💰 Prix matériaux'!$B$8)+IF(J24="",0,J24*'💰 Prix matériaux'!$B$9)+IF(K24="",0,K24*'💰 Prix matériaux'!$B$10)+IF(L24="",0,L24*'💰 Prix matériaux'!$B$11)+IF(M24="",0,M24*'💰 Prix matériaux'!$B$12)+IF(N24="",0,N24*'💰 Prix matériaux'!$B$13)+IF(O24="",0,O24*'💰 Prix matériaux'!$B$15)+IF(P24="",0,P24*'💰 Prix matériaux'!$B$16) -> 74 | R24: =C24+Q24 -> 104
A25: Altmer | B25: Dague | C25: 30 | D25: 1 | G25: 1 | I25: 1 | M25: 1 | Q25: =IF(D25="",0,D25*'💰 Prix matériaux'!$B$3)+IF(E25="",0,E25*'💰 Prix matériaux'!$B$4)+IF(F25="",0,F25*'💰 Prix matériaux'!$B$5)+IF(G25="",0,G25*'💰 Prix matériaux'!$B$6)+IF(H25="",0,H25*'💰 Prix matériaux'!$B$7)+IF(I25="",0,I25*'💰 Prix matériaux'!$B$8)+IF(J25="",0,J25*'💰 Prix matériaux'!$B$9)+IF(K25="",0,K25*'💰 Prix matériaux'!$B$10)+IF(L25="",0,L25*'💰 Prix matériaux'!$B$11)+IF(M25="",0,M25*'💰 Prix matériaux'!$B$12)+IF(N25="",0,N25*'💰 Prix matériaux'!$B$13)+IF(O25="",0,O25*'💰 Prix matériaux'!$B$15)+IF(P25="",0,P25*'💰 Prix matériaux'!$B$16) -> 55 | R25: =C25+Q25 -> 85
A26: Altmer | B26: Espadon | C26: 30 | D26: 2 | G26: 1 | I26: 2 | M26: 3 | Q26: =IF(D26="",0,D26*'💰 Prix matériaux'!$B$3)+IF(E26="",0,E26*'💰 Prix matériaux'!$B$4)+IF(F26="",0,F26*'💰 Prix matériaux'!$B$5)+IF(G26="",0,G26*'💰 Prix matériaux'!$B$6)+IF(H26="",0,H26*'💰 Prix matériaux'!$B$7)+IF(I26="",0,I26*'💰 Prix matériaux'!$B$8)+IF(J26="",0,J26*'💰 Prix matériaux'!$B$9)+IF(K26="",0,K26*'💰 Prix matériaux'!$B$10)+IF(L26="",0,L26*'💰 Prix matériaux'!$B$11)+IF(M26="",0,M26*'💰 Prix matériaux'!$B$12)+IF(N26="",0,N26*'💰 Prix matériaux'!$B$13)+IF(O26="",0,O26*'💰 Prix matériaux'!$B$15)+IF(P26="",0,P26*'💰 Prix matériaux'!$B$16) -> 85 | R26: =C26+Q26 -> 115
A27: Altmer | B27: Flèche | C27: 30 | I27: 1 | K27: 1 | Q27: =IF(D27="",0,D27*'💰 Prix matériaux'!$B$3)+IF(E27="",0,E27*'💰 Prix matériaux'!$B$4)+IF(F27="",0,F27*'💰 Prix matériaux'!$B$5)+IF(G27="",0,G27*'💰 Prix matériaux'!$B$6)+IF(H27="",0,H27*'💰 Prix matériaux'!$B$7)+IF(I27="",0,I27*'💰 Prix matériaux'!$B$8)+IF(J27="",0,J27*'💰 Prix matériaux'!$B$9)+IF(K27="",0,K27*'💰 Prix matériaux'!$B$10)+IF(L27="",0,L27*'💰 Prix matériaux'!$B$11)+IF(M27="",0,M27*'💰 Prix matériaux'!$B$12)+IF(N27="",0,N27*'💰 Prix matériaux'!$B$13)+IF(O27="",0,O27*'💰 Prix matériaux'!$B$15)+IF(P27="",0,P27*'💰 Prix matériaux'!$B$16) -> 25 | R27: =C27+Q27 -> 55
A28: Altmer | B28: Hache d'arme | C28: 30 | D28: 2 | G28: 1 | I28: 2 | M28: 2 | Q28: =IF(D28="",0,D28*'💰 Prix matériaux'!$B$3)+IF(E28="",0,E28*'💰 Prix matériaux'!$B$4)+IF(F28="",0,F28*'💰 Prix matériaux'!$B$5)+IF(G28="",0,G28*'💰 Prix matériaux'!$B$6)+IF(H28="",0,H28*'💰 Prix matériaux'!$B$7)+IF(I28="",0,I28*'💰 Prix matériaux'!$B$8)+IF(J28="",0,J28*'💰 Prix matériaux'!$B$9)+IF(K28="",0,K28*'💰 Prix matériaux'!$B$10)+IF(L28="",0,L28*'💰 Prix matériaux'!$B$11)+IF(M28="",0,M28*'💰 Prix matériaux'!$B$12)+IF(N28="",0,N28*'💰 Prix matériaux'!$B$13)+IF(O28="",0,O28*'💰 Prix matériaux'!$B$15)+IF(P28="",0,P28*'💰 Prix matériaux'!$B$16) -> 84 | R28: =C28+Q28 -> 114
A29: Altmer | B29: Hache | C29: 30 | D29: 1 | G29: 1 | I29: 1 | M29: 2 | Q29: =IF(D29="",0,D29*'💰 Prix matériaux'!$B$3)+IF(E29="",0,E29*'💰 Prix matériaux'!$B$4)+IF(F29="",0,F29*'💰 Prix matériaux'!$B$5)+IF(G29="",0,G29*'💰 Prix matériaux'!$B$6)+IF(H29="",0,H29*'💰 Prix matériaux'!$B$7)+IF(I29="",0,I29*'💰 Prix matériaux'!$B$8)+IF(J29="",0,J29*'💰 Prix matériaux'!$B$9)+IF(K29="",0,K29*'💰 Prix matériaux'!$B$10)+IF(L29="",0,L29*'💰 Prix matériaux'!$B$11)+IF(M29="",0,M29*'💰 Prix matériaux'!$B$12)+IF(N29="",0,N29*'💰 Prix matériaux'!$B$13)+IF(O29="",0,O29*'💰 Prix matériaux'!$B$15)+IF(P29="",0,P29*'💰 Prix matériaux'!$B$16) -> 56 | R29: =C29+Q29 -> 86
A30: Altmer | B30: Marteau de guerre | C30: 30 | D30: 2 | G30: 1 | I30: 2 | M30: 3 | Q30: =IF(D30="",0,D30*'💰 Prix matériaux'!$B$3)+IF(E30="",0,E30*'💰 Prix matériaux'!$B$4)+IF(F30="",0,F30*'💰 Prix matériaux'!$B$5)+IF(G30="",0,G30*'💰 Prix matériaux'!$B$6)+IF(H30="",0,H30*'💰 Prix matériaux'!$B$7)+IF(I30="",0,I30*'💰 Prix matériaux'!$B$8)+IF(J30="",0,J30*'💰 Prix matériaux'!$B$9)+IF(K30="",0,K30*'💰 Prix matériaux'!$B$10)+IF(L30="",0,L30*'💰 Prix matériaux'!$B$11)+IF(M30="",0,M30*'💰 Prix matériaux'!$B$12)+IF(N30="",0,N30*'💰 Prix matériaux'!$B$13)+IF(O30="",0,O30*'💰 Prix matériaux'!$B$15)+IF(P30="",0,P30*'💰 Prix matériaux'!$B$16) -> 85 | R30: =C30+Q30 -> 115
A31: Altmer | B31: Masse | C31: 30 | D31: 1 | G31: 1 | I31: 2 | M31: 1 | Q31: =IF(D31="",0,D31*'💰 Prix matériaux'!$B$3)+IF(E31="",0,E31*'💰 Prix matériaux'!$B$4)+IF(F31="",0,F31*'💰 Prix matériaux'!$B$5)+IF(G31="",0,G31*'💰 Prix matériaux'!$B$6)+IF(H31="",0,H31*'💰 Prix matériaux'!$B$7)+IF(I31="",0,I31*'💰 Prix matériaux'!$B$8)+IF(J31="",0,J31*'💰 Prix matériaux'!$B$9)+IF(K31="",0,K31*'💰 Prix matériaux'!$B$10)+IF(L31="",0,L31*'💰 Prix matériaux'!$B$11)+IF(M31="",0,M31*'💰 Prix matériaux'!$B$12)+IF(N31="",0,N31*'💰 Prix matériaux'!$B$13)+IF(O31="",0,O31*'💰 Prix matériaux'!$B$15)+IF(P31="",0,P31*'💰 Prix matériaux'!$B$16) -> 79 | R31: =C31+Q31 -> 109
A32: Altmer | B32: Épée | C32: 30 | D32: 1 | G32: 1 | I32: 1 | M32: 1 | Q32: =IF(D32="",0,D32*'💰 Prix matériaux'!$B$3)+IF(E32="",0,E32*'💰 Prix matériaux'!$B$4)+IF(F32="",0,F32*'💰 Prix matériaux'!$B$5)+IF(G32="",0,G32*'💰 Prix matériaux'!$B$6)+IF(H32="",0,H32*'💰 Prix matériaux'!$B$7)+IF(I32="",0,I32*'💰 Prix matériaux'!$B$8)+IF(J32="",0,J32*'💰 Prix matériaux'!$B$9)+IF(K32="",0,K32*'💰 Prix matériaux'!$B$10)+IF(L32="",0,L32*'💰 Prix matériaux'!$B$11)+IF(M32="",0,M32*'💰 Prix matériaux'!$B$12)+IF(N32="",0,N32*'💰 Prix matériaux'!$B$13)+IF(O32="",0,O32*'💰 Prix matériaux'!$B$15)+IF(P32="",0,P32*'💰 Prix matériaux'!$B$16) -> 55 | R32: =C32+Q32 -> 85
A33: BOSMER
A34: Bosmer | B34: Arc | C34: 30 | G34: 1 | I34: 2 | Q34: =IF(D34="",0,D34*'💰 Prix matériaux'!$B$3)+IF(E34="",0,E34*'💰 Prix matériaux'!$B$4)+IF(F34="",0,F34*'💰 Prix matériaux'!$B$5)+IF(G34="",0,G34*'💰 Prix matériaux'!$B$6)+IF(H34="",0,H34*'💰 Prix matériaux'!$B$7)+IF(I34="",0,I34*'💰 Prix matériaux'!$B$8)+IF(J34="",0,J34*'💰 Prix matériaux'!$B$9)+IF(K34="",0,K34*'💰 Prix matériaux'!$B$10)+IF(L34="",0,L34*'💰 Prix matériaux'!$B$11)+IF(M34="",0,M34*'💰 Prix matériaux'!$B$12)+IF(N34="",0,N34*'💰 Prix matériaux'!$B$13)+IF(O34="",0,O34*'💰 Prix matériaux'!$B$15)+IF(P34="",0,P34*'💰 Prix matériaux'!$B$16) -> 74 | R34: =C34+Q34 -> 104
A35: Bosmer | B35: Épée | C35: 30 | D35: 1 | G35: 1 | I35: 1 | M35: 1 | Q35: =IF(D35="",0,D35*'💰 Prix matériaux'!$B$3)+IF(E35="",0,E35*'💰 Prix matériaux'!$B$4)+IF(F35="",0,F35*'💰 Prix matériaux'!$B$5)+IF(G35="",0,G35*'💰 Prix matériaux'!$B$6)+IF(H35="",0,H35*'💰 Prix matériaux'!$B$7)+IF(I35="",0,I35*'💰 Prix matériaux'!$B$8)+IF(J35="",0,J35*'💰 Prix matériaux'!$B$9)+IF(K35="",0,K35*'💰 Prix matériaux'!$B$10)+IF(L35="",0,L35*'💰 Prix matériaux'!$B$11)+IF(M35="",0,M35*'💰 Prix matériaux'!$B$12)+IF(N35="",0,N35*'💰 Prix matériaux'!$B$13)+IF(O35="",0,O35*'💰 Prix matériaux'!$B$15)+IF(P35="",0,P35*'💰 Prix matériaux'!$B$16) -> 55 | R35: =C35+Q35 -> 85
A36: COMMUNE
A37: Commune | B37: Arc | C37: 15 | E37: 3 | M37: 1 | Q37: =IF(D37="",0,D37*'💰 Prix matériaux'!$B$3)+IF(E37="",0,E37*'💰 Prix matériaux'!$B$4)+IF(F37="",0,F37*'💰 Prix matériaux'!$B$5)+IF(G37="",0,G37*'💰 Prix matériaux'!$B$6)+IF(H37="",0,H37*'💰 Prix matériaux'!$B$7)+IF(I37="",0,I37*'💰 Prix matériaux'!$B$8)+IF(J37="",0,J37*'💰 Prix matériaux'!$B$9)+IF(K37="",0,K37*'💰 Prix matériaux'!$B$10)+IF(L37="",0,L37*'💰 Prix matériaux'!$B$11)+IF(M37="",0,M37*'💰 Prix matériaux'!$B$12)+IF(N37="",0,N37*'💰 Prix matériaux'!$B$13)+IF(O37="",0,O37*'💰 Prix matériaux'!$B$15)+IF(P37="",0,P37*'💰 Prix matériaux'!$B$16) -> 22 | R37: =C37+Q37 -> 37
A38: Commune | B38: Dague | C38: 15 | D38: 1 | I38: 1 | M38: 1 | Q38: =IF(D38="",0,D38*'💰 Prix matériaux'!$B$3)+IF(E38="",0,E38*'💰 Prix matériaux'!$B$4)+IF(F38="",0,F38*'💰 Prix matériaux'!$B$5)+IF(G38="",0,G38*'💰 Prix matériaux'!$B$6)+IF(H38="",0,H38*'💰 Prix matériaux'!$B$7)+IF(I38="",0,I38*'💰 Prix matériaux'!$B$8)+IF(J38="",0,J38*'💰 Prix matériaux'!$B$9)+IF(K38="",0,K38*'💰 Prix matériaux'!$B$10)+IF(L38="",0,L38*'💰 Prix matériaux'!$B$11)+IF(M38="",0,M38*'💰 Prix matériaux'!$B$12)+IF(N38="",0,N38*'💰 Prix matériaux'!$B$13)+IF(O38="",0,O38*'💰 Prix matériaux'!$B$15)+IF(P38="",0,P38*'💰 Prix matériaux'!$B$16) -> 29 | R38: =C38+Q38 -> 44
A39: Commune | B39: Hache | C39: 15 | D39: 1 | I39: 1 | M39: 2 | Q39: =IF(D39="",0,D39*'💰 Prix matériaux'!$B$3)+IF(E39="",0,E39*'💰 Prix matériaux'!$B$4)+IF(F39="",0,F39*'💰 Prix matériaux'!$B$5)+IF(G39="",0,G39*'💰 Prix matériaux'!$B$6)+IF(H39="",0,H39*'💰 Prix matériaux'!$B$7)+IF(I39="",0,I39*'💰 Prix matériaux'!$B$8)+IF(J39="",0,J39*'💰 Prix matériaux'!$B$9)+IF(K39="",0,K39*'💰 Prix matériaux'!$B$10)+IF(L39="",0,L39*'💰 Prix matériaux'!$B$11)+IF(M39="",0,M39*'💰 Prix matériaux'!$B$12)+IF(N39="",0,N39*'💰 Prix matériaux'!$B$13)+IF(O39="",0,O39*'💰 Prix matériaux'!$B$15)+IF(P39="",0,P39*'💰 Prix matériaux'!$B$16) -> 30 | R39: =C39+Q39 -> 45
A40: Commune | B40: Hache d'arme | C40: 15 | D40: 3 | I40: 1 | M40: 2 | Q40: =IF(D40="",0,D40*'💰 Prix matériaux'!$B$3)+IF(E40="",0,E40*'💰 Prix matériaux'!$B$4)+IF(F40="",0,F40*'💰 Prix matériaux'!$B$5)+IF(G40="",0,G40*'💰 Prix matériaux'!$B$6)+IF(H40="",0,H40*'💰 Prix matériaux'!$B$7)+IF(I40="",0,I40*'💰 Prix matériaux'!$B$8)+IF(J40="",0,J40*'💰 Prix matériaux'!$B$9)+IF(K40="",0,K40*'💰 Prix matériaux'!$B$10)+IF(L40="",0,L40*'💰 Prix matériaux'!$B$11)+IF(M40="",0,M40*'💰 Prix matériaux'!$B$12)+IF(N40="",0,N40*'💰 Prix matériaux'!$B$13)+IF(O40="",0,O40*'💰 Prix matériaux'!$B$15)+IF(P40="",0,P40*'💰 Prix matériaux'!$B$16) -> 38 | R40: =C40+Q40 -> 53
...

Sheet 🛡 Armures
A1: 🛡 FORGERON DE SOLITUDE — Pièces d'Armure
A2: Catégorie | B2: Pièce | C2: Type | D2: M.O. | E2: Fer | F2: Acier | G2: Orichalque | H2: Vif-argent | I2: Métal dwemer | J2: Pierre de lune | K2: Corindon | L2: Petit bois | M2: Cuir | N2: Bande cuir | O2: Or | P2: Malachite | Q2: Ébonite | R2: Coût mat. | S2: ⚡ TOTAL
A3: COMMON LÉGER
A4: Common Léger | B4: Armure — torse (5 var.) | C4: Légère | D4: 15 | M4: 4 | N4: 3 | R4: =IF(E4="",0,E4*'💰 Prix matériaux'!$B$3)+IF(F4="",0,F4*'💰 Prix matériaux'!$B$4)+IF(G4="",0,G4*'💰 Prix matériaux'!$B$5)+IF(H4="",0,H4*'💰 Prix matériaux'!$B$6)+IF(I4="",0,I4*'💰 Prix matériaux'!$B$7)+IF(J4="",0,J4*'💰 Prix matériaux'!$B$8)+IF(K4="",0,K4*'💰 Prix matériaux'!$B$9)+IF(L4="",0,L4*'💰 Prix matériaux'!$B$10)+IF(M4="",0,M4*'💰 Prix matériaux'!$B$11)+IF(N4="",0,N4*'💰 Prix matériaux'!$B$12)+IF(O4="",0,O4*'💰 Prix matériaux'!$B$13)+IF(P4="",0,P4*'💰 Prix matériaux'!$B$15)+IF(Q4="",0,Q4*'💰 Prix matériaux'!$B$16) -> 19 | S4: =D4+R4 -> 34
A5: Common Léger | B5: Gants (2 var.) | C5: Légère | D5: 15 | M5: 1 | N5: 2 | R5: =IF(E5="",0,E5*'💰 Prix matériaux'!$B$3)+IF(F5="",0,F5*'💰 Prix matériaux'!$B$4)+IF(G5="",0,G5*'💰 Prix matériaux'!$B$5)+IF(H5="",0,H5*'💰 Prix matériaux'!$B$6)+IF(I5="",0,I5*'💰 Prix matériaux'!$B$7)+IF(J5="",0,J5*'💰 Prix matériaux'!$B$8)+IF(K5="",0,K5*'💰 Prix matériaux'!$B$9)+IF(L5="",0,L5*'💰 Prix matériaux'!$B$10)+IF(M5="",0,M5*'💰 Prix matériaux'!$B$11)+IF(N5="",0,N5*'💰 Prix matériaux'!$B$12)+IF(O5="",0,O5*'💰 Prix matériaux'!$B$13)+IF(P5="",0,P5*'💰 Prix matériaux'!$B$15)+IF(Q5="",0,Q5*'💰 Prix matériaux'!$B$16) -> 6 | S5: =D5+R5 -> 21
A6: Common Léger | B6: Bottes (var.) | C6: Légère | D6: 15 | M6: 2 | N6: 2 | R6: =IF(E6="",0,E6*'💰 Prix matériaux'!$B$3)+IF(F6="",0,F6*'💰 Prix matériaux'!$B$4)+IF(G6="",0,G6*'💰 Prix matériaux'!$B$5)+IF(H6="",0,H6*'💰 Prix matériaux'!$B$6)+IF(I6="",0,I6*'💰 Prix matériaux'!$B$7)+IF(J6="",0,J6*'💰 Prix matériaux'!$B$8)+IF(K6="",0,K6*'💰 Prix matériaux'!$B$9)+IF(L6="",0,L6*'💰 Prix matériaux'!$B$10)+IF(M6="",0,M6*'💰 Prix matériaux'!$B$11)+IF(N6="",0,N6*'💰 Prix matériaux'!$B$12)+IF(O6="",0,O6*'💰 Prix matériaux'!$B$13)+IF(P6="",0,P6*'💰 Prix matériaux'!$B$15)+IF(Q6="",0,Q6*'💰 Prix matériaux'!$B$16) -> 10 | S6: =D6+R6 -> 25
A7: COMMON LOURD
A8: Common Lourd | B8: Armure de mailles (2 var.) | C8: Lourde | D8: 15 | E8: 5 | N8: 3 | R8: =IF(E8="",0,E8*'💰 Prix matériaux'!$B$3)+IF(F8="",0,F8*'💰 Prix matériaux'!$B$4)+IF(G8="",0,G8*'💰 Prix matériaux'!$B$5)+IF(H8="",0,H8*'💰 Prix matériaux'!$B$6)+IF(I8="",0,I8*'💰 Prix matériaux'!$B$7)+IF(J8="",0,J8*'💰 Prix matériaux'!$B$8)+IF(K8="",0,K8*'💰 Prix matériaux'!$B$9)+IF(L8="",0,L8*'💰 Prix matériaux'!$B$10)+IF(M8="",0,M8*'💰 Prix matériaux'!$B$11)+IF(N8="",0,N8*'💰 Prix matériaux'!$B$12)+IF(O8="",0,O8*'💰 Prix matériaux'!$B$13)+IF(P8="",0,P8*'💰 Prix matériaux'!$B$15)+IF(Q8="",0,Q8*'💰 Prix matériaux'!$B$16) -> 23 | S8: =D8+R8 -> 38
A9: FOURRURE
A10: Fourrure | B10: Armure | C10: Légère | D10: 5 | M10: 5 | N10: 3 | R10: =IF(E10="",0,E10*'💰 Prix matériaux'!$B$3)+IF(F10="",0,F10*'💰 Prix matériaux'!$B$4)+IF(G10="",0,G10*'💰 Prix matériaux'!$B$5)+IF(H10="",0,H10*'💰 Prix matériaux'!$B$6)+IF(I10="",0,I10*'💰 Prix matériaux'!$B$7)+IF(J10="",0,J10*'💰 Prix matériaux'!$B$8)+IF(K10="",0,K10*'💰 Prix matériaux'!$B$9)+IF(L10="",0,L10*'💰 Prix matériaux'!$B$10)+IF(M10="",0,M10*'💰 Prix matériaux'!$B$11)+IF(N10="",0,N10*'💰 Prix matériaux'!$B$12)+IF(O10="",0,O10*'💰 Prix matériaux'!$B$13)+IF(P10="",0,P10*'💰 Prix matériaux'!$B$15)+IF(Q10="",0,Q10*'💰 Prix matériaux'!$B$16) -> 23 | S10: =D10+R10 -> 28
A11: Fourrure | B11: Bottes | C11: Légère | D11: 5 | M11: 2 | N11: 2 | R11: =IF(E11="",0,E11*'💰 Prix matériaux'!$B$3)+IF(F11="",0,F11*'💰 Prix matériaux'!$B$4)+IF(G11="",0,G11*'💰 Prix matériaux'!$B$5)+IF(H11="",0,H11*'💰 Prix matériaux'!$B$6)+IF(I11="",0,I11*'💰 Prix matériaux'!$B$7)+IF(J11="",0,J11*'💰 Prix matériaux'!$B$8)+IF(K11="",0,K11*'💰 Prix matériaux'!$B$9)+IF(L11="",0,L11*'💰 Prix matériaux'!$B$10)+IF(M11="",0,M11*'💰 Prix matériaux'!$B$11)+IF(N11="",0,N11*'💰 Prix matériaux'!$B$12)+IF(O11="",0,O11*'💰 Prix matériaux'!$B$13)+IF(P11="",0,P11*'💰 Prix matériaux'!$B$15)+IF(Q11="",0,Q11*'💰 Prix matériaux'!$B$16) -> 10 | S11: =D11+R11 -> 15
A12: Fourrure | B12: Casque | C12: Légère | D12: 5 | M12: 2 | N12: 1 | R12: =IF(E12="",0,E12*'💰 Prix matériaux'!$B$3)+IF(F12="",0,F12*'💰 Prix matériaux'!$B$4)+IF(G12="",0,G12*'💰 Prix matériaux'!$B$5)+IF(H12="",0,H12*'💰 Prix matériaux'!$B$6)+IF(I12="",0,I12*'💰 Prix matériaux'!$B$7)+IF(J12="",0,J12*'💰 Prix matériaux'!$B$8)+IF(K12="",0,K12*'💰 Prix matériaux'!$B$9)+IF(L12="",0,L12*'💰 Prix matériaux'!$B$10)+IF(M12="",0,M12*'💰 Prix matériaux'!$B$11)+IF(N12="",0,N12*'💰 Prix matériaux'!$B$12)+IF(O12="",0,O12*'💰 Prix matériaux'!$B$13)+IF(P12="",0,P12*'💰 Prix matériaux'!$B$15)+IF(Q12="",0,Q12*'💰 Prix matériaux'!$B$16) -> 9 | S12: =D12+R12 -> 14
A13: Fourrure | B13: Gantelets | C13: Légère | D13: 5 | M13: 1 | N13: 2 | R13: =IF(E13="",0,E13*'💰 Prix matériaux'!$B$3)+IF(F13="",0,F13*'💰 Prix matériaux'!$B$4)+IF(G13="",0,G13*'💰 Prix matériaux'!$B$5)+IF(H13="",0,H13*'💰 Prix matériaux'!$B$6)+IF(I13="",0,I13*'💰 Prix matériaux'!$B$7)+IF(J13="",0,J13*'💰 Prix matériaux'!$B$8)+IF(K13="",0,K13*'💰 Prix matériaux'!$B$9)+IF(L13="",0,L13*'💰 Prix matériaux'!$B$10)+IF(M13="",0,M13*'💰 Prix matériaux'!$B$11)+IF(N13="",0,N13*'💰 Prix matériaux'!$B$12)+IF(O13="",0,O13*'💰 Prix matériaux'!$B$13)+IF(P13="",0,P13*'💰 Prix matériaux'!$B$15)+IF(Q13="",0,Q13*'💰 Prix matériaux'!$B$16) -> 6 | S13: =D13+R13 -> 11
A14: Fourrure | B14: Bouclier | C14: Légère | D14: 5 | M14: 4 | N14: 2 | R14: =IF(E14="",0,E14*'💰 Prix matériaux'!$B$3)+IF(F14="",0,F14*'💰 Prix matériaux'!$B$4)+IF(G14="",0,G14*'💰 Prix matériaux'!$B$5)+IF(H14="",0,H14*'💰 Prix matériaux'!$B$6)+IF(I14="",0,I14*'💰 Prix matériaux'!$B$7)+IF(J14="",0,J14*'💰 Prix matériaux'!$B$8)+IF(K14="",0,K14*'💰 Prix matériaux'!$B$9)+IF(L14="",0,L14*'💰 Prix matériaux'!$B$10)+IF(M14="",0,M14*'💰 Prix matériaux'!$B$11)+IF(N14="",0,N14*'💰 Prix matériaux'!$B$12)+IF(O14="",0,O14*'💰 Prix matériaux'!$B$13)+IF(P14="",0,P14*'💰 Prix matériaux'!$B$15)+IF(Q14="",0,Q14*'💰 Prix matériaux'!$B$16) -> 18 | S14: =D14+R14 -> 23
A15: Fourrure | B15: Collier | C15: Légère | D15: 5 | M15: 2 | N15: 1 | R15: =IF(E15="",0,E15*'💰 Prix matériaux'!$B$3)+IF(F15="",0,F15*'💰 Prix matériaux'!$B$4)+IF(G15="",0,G15*'💰 Prix matériaux'!$B$5)+IF(H15="",0,H15*'💰 Prix matériaux'!$B$6)+IF(I15="",0,I15*'💰 Prix matériaux'!$B$7)+IF(J15="",0,J15*'💰 Prix matériaux'!$B$8)+IF(K15="",0,K15*'💰 Prix matériaux'!$B$9)+IF(L15="",0,L15*'💰 Prix matériaux'!$B$10)+IF(M15="",0,M15*'💰 Prix matériaux'!$B$11)+IF(N15="",0,N15*'💰 Prix matériaux'!$B$12)+IF(O15="",0,O15*'💰 Prix matériaux'!$B$13)+IF(P15="",0,P15*'💰 Prix matériaux'!$B$15)+IF(Q15="",0,Q15*'💰 Prix matériaux'!$B$16) -> 9 | S15: =D15+R15 -> 14
A16: Fourrure | B16: Large Collier | C16: Légère | D16: 5 | M16: 2 | N16: 1 | R16: =IF(E16="",0,E16*'💰 Prix matériaux'!$B$3)+IF(F16="",0,F16*'💰 Prix matériaux'!$B$4)+IF(G16="",0,G16*'💰 Prix matériaux'!$B$5)+IF(H16="",0,H16*'💰 Prix matériaux'!$B$6)+IF(I16="",0,I16*'💰 Prix matériaux'!$B$7)+IF(J16="",0,J16*'💰 Prix matériaux'!$B$8)+IF(K16="",0,K16*'💰 Prix matériaux'!$B$9)+IF(L16="",0,L16*'💰 Prix matériaux'!$B$10)+IF(M16="",0,M16*'💰 Prix matériaux'!$B$11)+IF(N16="",0,N16*'💰 Prix matériaux'!$B$12)+IF(O16="",0,O16*'💰 Prix matériaux'!$B$13)+IF(P16="",0,P16*'💰 Prix matériaux'!$B$15)+IF(Q16="",0,Q16*'💰 Prix matériaux'!$B$16) -> 9 | S16: =D16+R16 -> 14
A17: Fourrure | B17: Shawl | C17: Légère | D17: 5 | M17: 6 | N17: 3 | R17: =IF(E17="",0,E17*'💰 Prix matériaux'!$B$3)+IF(F17="",0,F17*'💰 Prix matériaux'!$B$4)+IF(G17="",0,G17*'💰 Prix matériaux'!$B$5)+IF(H17="",0,H17*'💰 Prix matériaux'!$B$6)+IF(I17="",0,I17*'💰 Prix matériaux'!$B$7)+IF(J17="",0,J17*'💰 Prix matériaux'!$B$8)+IF(K17="",0,K17*'💰 Prix matériaux'!$B$9)+IF(L17="",0,L17*'💰 Prix matériaux'!$B$10)+IF(M17="",0,M17*'💰 Prix matériaux'!$B$11)+IF(N17="",0,N17*'💰 Prix matériaux'!$B$12)+IF(O17="",0,O17*'💰 Prix matériaux'!$B$13)+IF(P17="",0,P17*'💰 Prix matériaux'!$B$15)+IF(Q17="",0,Q17*'💰 Prix matériaux'!$B$16) -> 27 | S17: =D17+R17 -> 32
A18: Fourrure | B18: Skirt | C18: Légère | D18: 5 | M18: 5 | N18: 3 | R18: =IF(E18="",0,E18*'💰 Prix matériaux'!$B$3)+IF(F18="",0,F18*'💰 Prix matériaux'!$B$4)+IF(G18="",0,G18*'💰 Prix matériaux'!$B$5)+IF(H18="",0,H18*'💰 Prix matériaux'!$B$6)+IF(I18="",0,I18*'💰 Prix matériaux'!$B$7)+IF(J18="",0,J18*'💰 Prix matériaux'!$B$8)+IF(K18="",0,K18*'💰 Prix matériaux'!$B$9)+IF(L18="",0,L18*'💰 Prix matériaux'!$B$10)+IF(M18="",0,M18*'💰 Prix matériaux'!$B$11)+IF(N18="",0,N18*'💰 Prix matériaux'!$B$12)+IF(O18="",0,O18*'💰 Prix matériaux'!$B$13)+IF(P18="",0,P18*'💰 Prix matériaux'!$B$15)+IF(Q18="",0,Q18*'💰 Prix matériaux'!$B$16) -> 23 | S18: =D18+R18 -> 28
A19: HUNTER'S FUR
A20: Hunter's Fur | B20: Coat | C20: Légère | D20: 5 | M20: 4 | N20: 3 | R20: =IF(E20="",0,E20*'💰 Prix matériaux'!$B$3)+IF(F20="",0,F20*'💰 Prix matériaux'!$B$4)+IF(G20="",0,G20*'💰 Prix matériaux'!$B$5)+IF(H20="",0,H20*'💰 Prix matériaux'!$B$6)+IF(I20="",0,I20*'💰 Prix matériaux'!$B$7)+IF(J20="",0,J20*'💰 Prix matériaux'!$B$8)+IF(K20="",0,K20*'💰 Prix matériaux'!$B$9)+IF(L20="",0,L20*'💰 Prix matériaux'!$B$10)+IF(M20="",0,M20*'💰 Prix matériaux'!$B$11)+IF(N20="",0,N20*'💰 Prix matériaux'!$B$12)+IF(O20="",0,O20*'💰 Prix matériaux'!$B$13)+IF(P20="",0,P20*'💰 Prix matériaux'!$B$15)+IF(Q20="",0,Q20*'💰 Prix matériaux'!$B$16) -> 19 | S20: =D20+R20 -> 24
A21: Hunter's Fur | B21: Bottes | C21: Légère | D21: 5 | M21: 2 | N21: 2 | R21: =IF(E21="",0,E21*'💰 Prix matériaux'!$B$3)+IF(F21="",0,F21*'💰 Prix matériaux'!$B$4)+IF(G21="",0,G21*'💰 Prix matériaux'!$B$5)+IF(H21="",0,H21*'💰 Prix matériaux'!$B$6)+IF(I21="",0,I21*'💰 Prix matériaux'!$B$7)+IF(J21="",0,J21*'💰 Prix matériaux'!$B$8)+IF(K21="",0,K21*'💰 Prix matériaux'!$B$9)+IF(L21="",0,L21*'💰 Prix matériaux'!$B$10)+IF(M21="",0,M21*'💰 Prix matériaux'!$B$11)+IF(N21="",0,N21*'💰 Prix matériaux'!$B$12)+IF(O21="",0,O21*'💰 Prix matériaux'!$B$13)+IF(P21="",0,P21*'💰 Prix matériaux'!$B$15)+IF(Q21="",0,Q21*'💰 Prix matériaux'!$B$16) -> 10 | S21: =D21+R21 -> 15
A22: Hunter's Fur | B22: Hat | C22: Légère | D22: 5 | M22: 2 | N22: 1 | R22: =IF(E22="",0,E22*'💰 Prix matériaux'!$B$3)+IF(F22="",0,F22*'💰 Prix matériaux'!$B$4)+IF(G22="",0,G22*'💰 Prix matériaux'!$B$5)+IF(H22="",0,H22*'💰 Prix matériaux'!$B$6)+IF(I22="",0,I22*'💰 Prix matériaux'!$B$7)+IF(J22="",0,J22*'💰 Prix matériaux'!$B$8)+IF(K22="",0,K22*'💰 Prix matériaux'!$B$9)+IF(L22="",0,L22*'💰 Prix matériaux'!$B$10)+IF(M22="",0,M22*'💰 Prix matériaux'!$B$11)+IF(N22="",0,N22*'💰 Prix matériaux'!$B$12)+IF(O22="",0,O22*'💰 Prix matériaux'!$B$13)+IF(P22="",0,P22*'💰 Prix matériaux'!$B$15)+IF(Q22="",0,Q22*'💰 Prix matériaux'!$B$16) -> 9 | S22: =D22+R22 -> 14
A23: Hunter's Fur | B23: Gloves | C23: Légère | D23: 5 | M23: 1 | N23: 2 | R23: =IF(E23="",0,E23*'💰 Prix matériaux'!$B$3)+IF(F23="",0,F23*'💰 Prix matériaux'!$B$4)+IF(G23="",0,G23*'💰 Prix matériaux'!$B$5)+IF(H23="",0,H23*'💰 Prix matériaux'!$B$6)+IF(I23="",0,I23*'💰 Prix matériaux'!$B$7)+IF(J23="",0,J23*'💰 Prix matériaux'!$B$8)+IF(K23="",0,K23*'💰 Prix matériaux'!$B$9)+IF(L23="",0,L23*'💰 Prix matériaux'!$B$10)+IF(M23="",0,M23*'💰 Prix matériaux'!$B$11)+IF(N23="",0,N23*'💰 Prix matériaux'!$B$12)+IF(O23="",0,O23*'💰 Prix matériaux'!$B$13)+IF(P23="",0,P23*'💰 Prix matériaux'!$B$15)+IF(Q23="",0,Q23*'💰 Prix matériaux'!$B$16) -> 6 | S23: =D23+R23 -> 11
A24: Hunter's Fur | B24: Bouclier | C24: Légère | D24: 5 | M24: 4 | N24: 2 | R24: =IF(E24="",0,E24*'💰 Prix matériaux'!$B$3)+IF(F24="",0,F24*'💰 Prix matériaux'!$B$4)+IF(G24="",0,G24*'💰 Prix matériaux'!$B$5)+IF(H24="",0,H24*'💰 Prix matériaux'!$B$6)+IF(I24="",0,I24*'💰 Prix matériaux'!$B$7)+IF(J24="",0,J24*'💰 Prix matériaux'!$B$8)+IF(K24="",0,K24*'💰 Prix matériaux'!$B$9)+IF(L24="",0,L24*'💰 Prix matériaux'!$B$10)+IF(M24="",0,M24*'💰 Prix matériaux'!$B$11)+IF(N24="",0,N24*'💰 Prix matériaux'!$B$12)+IF(O24="",0,O24*'💰 Prix matériaux'!$B$13)+IF(P24="",0,P24*'💰 Prix matériaux'!$B$15)+IF(Q24="",0,Q24*'💰 Prix matériaux'!$B$16) -> 18 | S24: =D24+R24 -> 23
A25: NORTHERN FUR
A26: Northern Fur | B26: Coat | C26: Légère | D26: 5 | M26: 4 | N26: 3 | R26: =IF(E26="",0,E26*'💰 Prix matériaux'!$B$3)+IF(F26="",0,F26*'💰 Prix matériaux'!$B$4)+IF(G26="",0,G26*'💰 Prix matériaux'!$B$5)+IF(H26="",0,H26*'💰 Prix matériaux'!$B$6)+IF(I26="",0,I26*'💰 Prix matériaux'!$B$7)+IF(J26="",0,J26*'💰 Prix matériaux'!$B$8)+IF(K26="",0,K26*'💰 Prix matériaux'!$B$9)+IF(L26="",0,L26*'💰 Prix matériaux'!$B$10)+IF(M26="",0,M26*'💰 Prix matériaux'!$B$11)+IF(N26="",0,N26*'💰 Prix matériaux'!$B$12)+IF(O26="",0,O26*'💰 Prix matériaux'!$B$13)+IF(P26="",0,P26*'💰 Prix matériaux'!$B$15)+IF(Q26="",0,Q26*'💰 Prix matériaux'!$B$16) -> 19 | S26: =D26+R26 -> 24
A27: Northern Fur | B27: Bottes | C27: Légère | D27: 5 | M27: 2 | N27: 2 | R27: =IF(E27="",0,E27*'💰 Prix matériaux'!$B$3)+IF(F27="",0,F27*'💰 Prix matériaux'!$B$4)+IF(G27="",0,G27*'💰 Prix matériaux'!$B$5)+IF(H27="",0,H27*'💰 Prix matériaux'!$B$6)+IF(I27="",0,I27*'💰 Prix matériaux'!$B$7)+IF(J27="",0,J27*'💰 Prix matériaux'!$B$8)+IF(K27="",0,K27*'💰 Prix matériaux'!$B$9)+IF(L27="",0,L27*'💰 Prix matériaux'!$B$10)+IF(M27="",0,M27*'💰 Prix matériaux'!$B$11)+IF(N27="",0,N27*'💰 Prix matériaux'!$B$12)+IF(O27="",0,O27*'💰 Prix matériaux'!$B$13)+IF(P27="",0,P27*'💰 Prix matériaux'!$B$15)+IF(Q27="",0,Q27*'💰 Prix matériaux'!$B$16) -> 10 | S27: =D27+R27 -> 15
A28: Northern Fur | B28: Hat | C28: Légère | D28: 5 | M28: 2 | N28: 1 | R28: =IF(E28="",0,E28*'💰 Prix matériaux'!$B$3)+IF(F28="",0,F28*'💰 Prix matériaux'!$B$4)+IF(G28="",0,G28*'💰 Prix matériaux'!$B$5)+IF(H28="",0,H28*'💰 Prix matériaux'!$B$6)+IF(I28="",0,I28*'💰 Prix matériaux'!$B$7)+IF(J28="",0,J28*'💰 Prix matériaux'!$B$8)+IF(K28="",0,K28*'💰 Prix matériaux'!$B$9)+IF(L28="",0,L28*'💰 Prix matériaux'!$B$10)+IF(M28="",0,M28*'💰 Prix matériaux'!$B$11)+IF(N28="",0,N28*'💰 Prix matériaux'!$B$12)+IF(O28="",0,O28*'💰 Prix matériaux'!$B$13)+IF(P28="",0,P28*'💰 Prix matériaux'!$B$15)+IF(Q28="",0,Q28*'💰 Prix matériaux'!$B$16) -> 9 | S28: =D28+R28 -> 14
A29: Northern Fur | B29: Gloves | C29: Légère | D29: 5 | M29: 1 | N29: 2 | R29: =IF(E29="",0,E29*'💰 Prix matériaux'!$B$3)+IF(F29="",0,F29*'💰 Prix matériaux'!$B$4)+IF(G29="",0,G29*'💰 Prix matériaux'!$B$5)+IF(H29="",0,H29*'💰 Prix matériaux'!$B$6)+IF(I29="",0,I29*'💰 Prix matériaux'!$B$7)+IF(J29="",0,J29*'💰 Prix matériaux'!$B$8)+IF(K29="",0,K29*'💰 Prix matériaux'!$B$9)+IF(L29="",0,L29*'💰 Prix matériaux'!$B$10)+IF(M29="",0,M29*'💰 Prix matériaux'!$B$11)+IF(N29="",0,N29*'💰 Prix matériaux'!$B$12)+IF(O29="",0,O29*'💰 Prix matériaux'!$B$13)+IF(P29="",0,P29*'💰 Prix matériaux'!$B$15)+IF(Q29="",0,Q29*'💰 Prix matériaux'!$B$16) -> 6 | S29: =D29+R29 -> 11
A30: Northern Fur | B30: Bouclier | C30: Légère | D30: 5 | M30: 4 | N30: 2 | R30: =IF(E30="",0,E30*'💰 Prix matériaux'!$B$3)+IF(F30="",0,F30*'💰 Prix matériaux'!$B$4)+IF(G30="",0,G30*'💰 Prix matériaux'!$B$5)+IF(H30="",0,H30*'💰 Prix matériaux'!$B$6)+IF(I30="",0,I30*'💰 Prix matériaux'!$B$7)+IF(J30="",0,J30*'💰 Prix matériaux'!$B$8)+IF(K30="",0,K30*'💰 Prix matériaux'!$B$9)+IF(L30="",0,L30*'💰 Prix matériaux'!$B$10)+IF(M30="",0,M30*'💰 Prix matériaux'!$B$11)+IF(N30="",0,N30*'💰 Prix matériaux'!$B$12)+IF(O30="",0,O30*'💰 Prix matériaux'!$B$13)+IF(P30="",0,P30*'💰 Prix matériaux'!$B$15)+IF(Q30="",0,Q30*'💰 Prix matériaux'!$B$16) -> 18 | S30: =D30+R30 -> 23
A31: PEAU
A32: Peau | B32: Armure | C32: Légère | D32: 5 | M32: 4 | N32: 3 | R32: =IF(E32="",0,E32*'💰 Prix matériaux'!$B$3)+IF(F32="",0,F32*'💰 Prix matériaux'!$B$4)+IF(G32="",0,G32*'💰 Prix matériaux'!$B$5)+IF(H32="",0,H32*'💰 Prix matériaux'!$B$6)+IF(I32="",0,I32*'💰 Prix matériaux'!$B$7)+IF(J32="",0,J32*'💰 Prix matériaux'!$B$8)+IF(K32="",0,K32*'💰 Prix matériaux'!$B$9)+IF(L32="",0,L32*'💰 Prix matériaux'!$B$10)+IF(M32="",0,M32*'💰 Prix matériaux'!$B$11)+IF(N32="",0,N32*'💰 Prix matériaux'!$B$12)+IF(O32="",0,O32*'💰 Prix matériaux'!$B$13)+IF(P32="",0,P32*'💰 Prix matériaux'!$B$15)+IF(Q32="",0,Q32*'💰 Prix matériaux'!$B$16) -> 19 | S32: =D32+R32 -> 24
A33: Peau | B33: Bottes | C33: Légère | D33: 5 | M33: 2 | N33: 2 | R33: =IF(E33="",0,E33*'💰 Prix matériaux'!$B$3)+IF(F33="",0,F33*'💰 Prix matériaux'!$B$4)+IF(G33="",0,G33*'💰 Prix matériaux'!$B$5)+IF(H33="",0,H33*'💰 Prix matériaux'!$B$6)+IF(I33="",0,I33*'💰 Prix matériaux'!$B$7)+IF(J33="",0,J33*'💰 Prix matériaux'!$B$8)+IF(K33="",0,K33*'💰 Prix matériaux'!$B$9)+IF(L33="",0,L33*'💰 Prix matériaux'!$B$10)+IF(M33="",0,M33*'💰 Prix matériaux'!$B$11)+IF(N33="",0,N33*'💰 Prix matériaux'!$B$12)+IF(O33="",0,O33*'💰 Prix matériaux'!$B$13)+IF(P33="",0,P33*'💰 Prix matériaux'!$B$15)+IF(Q33="",0,Q33*'💰 Prix matériaux'!$B$16) -> 10 | S33: =D33+R33 -> 15
A34: Peau | B34: Casque | C34: Légère | D34: 5 | M34: 2 | N34: 1 | R34: =IF(E34="",0,E34*'💰 Prix matériaux'!$B$3)+IF(F34="",0,F34*'💰 Prix matériaux'!$B$4)+IF(G34="",0,G34*'💰 Prix matériaux'!$B$5)+IF(H34="",0,H34*'💰 Prix matériaux'!$B$6)+IF(I34="",0,I34*'💰 Prix matériaux'!$B$7)+IF(J34="",0,J34*'💰 Prix matériaux'!$B$8)+IF(K34="",0,K34*'💰 Prix matériaux'!$B$9)+IF(L34="",0,L34*'💰 Prix matériaux'!$B$10)+IF(M34="",0,M34*'💰 Prix matériaux'!$B$11)+IF(N34="",0,N34*'💰 Prix matériaux'!$B$12)+IF(O34="",0,O34*'💰 Prix matériaux'!$B$13)+IF(P34="",0,P34*'💰 Prix matériaux'!$B$15)+IF(Q34="",0,Q34*'💰 Prix matériaux'!$B$16) -> 9 | S34: =D34+R34 -> 14
A35: Peau | B35: Gantelets | C35: Légère | D35: 5 | M35: 1 | N35: 2 | R35: =IF(E35="",0,E35*'💰 Prix matériaux'!$B$3)+IF(F35="",0,F35*'💰 Prix matériaux'!$B$4)+IF(G35="",0,G35*'💰 Prix matériaux'!$B$5)+IF(H35="",0,H35*'💰 Prix matériaux'!$B$6)+IF(I35="",0,I35*'💰 Prix matériaux'!$B$7)+IF(J35="",0,J35*'💰 Prix matériaux'!$B$8)+IF(K35="",0,K35*'💰 Prix matériaux'!$B$9)+IF(L35="",0,L35*'💰 Prix matériaux'!$B$10)+IF(M35="",0,M35*'💰 Prix matériaux'!$B$11)+IF(N35="",0,N35*'💰 Prix matériaux'!$B$12)+IF(O35="",0,O35*'💰 Prix matériaux'!$B$13)+IF(P35="",0,P35*'💰 Prix matériaux'!$B$15)+IF(Q35="",0,Q35*'💰 Prix matériaux'!$B$16) -> 6 | S35: =D35+R35 -> 11
A36: Peau | B36: Bouclier | C36: Légère | D36: 5 | M36: 4 | N36: 2 | R36: =IF(E36="",0,E36*'💰 Prix matériaux'!$B$3)+IF(F36="",0,F36*'💰 Prix matériaux'!$B$4)+IF(G36="",0,G36*'💰 Prix matériaux'!$B$5)+IF(H36="",0,H36*'💰 Prix matériaux'!$B$6)+IF(I36="",0,I36*'💰 Prix matériaux'!$B$7)+IF(J36="",0,J36*'💰 Prix matériaux'!$B$8)+IF(K36="",0,K36*'💰 Prix matériaux'!$B$9)+IF(L36="",0,L36*'💰 Prix matériaux'!$B$10)+IF(M36="",0,M36*'💰 Prix matériaux'!$B$11)+IF(N36="",0,N36*'💰 Prix matériaux'!$B$12)+IF(O36="",0,O36*'💰 Prix matériaux'!$B$13)+IF(P36="",0,P36*'💰 Prix matériaux'!$B$15)+IF(Q36="",0,Q36*'💰 Prix matériaux'!$B$16) -> 18 | S36: =D36+R36 -> 23
A37: NORTHERN HIDE
A38: Northern Hide | B38: Bottes | C38: Légère | D38: 5 | M38: 2 | N38: 2 | R38: =IF(E38="",0,E38*'💰 Prix matériaux'!$B$3)+IF(F38="",0,F38*'💰 Prix matériaux'!$B$4)+IF(G38="",0,G38*'💰 Prix matériaux'!$B$5)+IF(H38="",0,H38*'💰 Prix matériaux'!$B$6)+IF(I38="",0,I38*'💰 Prix matériaux'!$B$7)+IF(J38="",0,J38*'💰 Prix matériaux'!$B$8)+IF(K38="",0,K38*'💰 Prix matériaux'!$B$9)+IF(L38="",0,L38*'💰 Prix matériaux'!$B$10)+IF(M38="",0,M38*'💰 Prix matériaux'!$B$11)+IF(N38="",0,N38*'💰 Prix matériaux'!$B$12)+IF(O38="",0,O38*'💰 Prix matériaux'!$B$13)+IF(P38="",0,P38*'💰 Prix matériaux'!$B$15)+IF(Q38="",0,Q38*'💰 Prix matériaux'!$B$16) -> 10 | S38: =D38+R38 -> 15
A39: Northern Hide | B39: Casque | C39: Légère | D39: 5 | M39: 2 | N39: 1 | R39: =IF(E39="",0,E39*'💰 Prix matériaux'!$B$3)+IF(F39="",0,F39*'💰 Prix matériaux'!$B$4)+IF(G39="",0,G39*'💰 Prix matériaux'!$B$5)+IF(H39="",0,H39*'💰 Prix matériaux'!$B$6)+IF(I39="",0,I39*'💰 Prix matériaux'!$B$7)+IF(J39="",0,J39*'💰 Prix matériaux'!$B$8)+IF(K39="",0,K39*'💰 Prix matériaux'!$B$9)+IF(L39="",0,L39*'💰 Prix matériaux'!$B$10)+IF(M39="",0,M39*'💰 Prix matériaux'!$B$11)+IF(N39="",0,N39*'💰 Prix matériaux'!$B$12)+IF(O39="",0,O39*'💰 Prix matériaux'!$B$13)+IF(P39="",0,P39*'💰 Prix matériaux'!$B$15)+IF(Q39="",0,Q39*'💰 Prix matériaux'!$B$16) -> 9 | S39: =D39+R39 -> 14
A40: Northern Hide | B40: Gantelets | C40: Légère | D40: 5 | M40: 1 | N40: 2 | R40: =IF(E40="",0,E40*'💰 Prix matériaux'!$B$3)+IF(F40="",0,F40*'💰 Prix matériaux'!$B$4)+IF(G40="",0,G40*'💰 Prix matériaux'!$B$5)+IF(H40="",0,H40*'💰 Prix matériaux'!$B$6)+IF(I40="",0,I40*'💰 Prix matériaux'!$B$7)+IF(J40="",0,J40*'💰 Prix matériaux'!$B$8)+IF(K40="",0,K40*'💰 Prix matériaux'!$B$9)+IF(L40="",0,L40*'💰 Prix matériaux'!$B$10)+IF(M40="",0,M40*'💰 Prix matériaux'!$B$11)+IF(N40="",0,N40*'💰 Prix matériaux'!$B$12)+IF(O40="",0,O40*'💰 Prix matériaux'!$B$13)+IF(P40="",0,P40*'💰 Prix matériaux'!$B$15)+IF(Q40="",0,Q40*'💰 Prix matériaux'!$B$16) -> 6 | S40: =D40+R40 -> 11
...

Sheet 💰 Prix matériaux
A2: Matériau | B2: Prix (sep.) | C2: Catégorie
A3: Lingot de fer | B3: 4 | C3: Métaux
A4: Lingot d'acier | B4: 7 | C4: Métaux
A5: Lingot d'orichalque | B5: 20 | C5: Métaux
A6: Lingot de vif-argent | B6: 26 | C6: Métaux
A7: Lingot de métal dwemer | B7: 50 | C7: Métaux
A8: Pierre de lune raffinée | B8: 24 | C8: Minerais raffinées
A9: Corindon raffiné | B9: 6 | C9: Minerais raffinées
A10: Petit bois | B10: 1 | C10: Matières naturelles
A11: Cuir | B11: 4 | C11: Matières naturelles
A12: Bande de cuir | B12: 1 | C12: Matières naturelles
A13: Lingot d'or | B13: 0 | C13: Métaux
A14: Lingot d'argent | B14: 0 | C14: Métaux
... A20: Coke coal | B20: 3 | C20: Combustibles
